Workbook
Name UPDATE: 'Data Sheet'!$E$1

Sheet Financials>
B2: ="Historical Financial Statements - "&'Data Sheet'!B1 -> Historical Financial Statements - TATA MOTORS PASSENGER VEHICLES LTD
B3: Years | C3: ='Data Sheet'!B16 -> 42460 | D3: ='Data Sheet'!C16 -> 42825 | E3: ='Data Sheet'!D16 -> 43190 | F3: ='Data Sheet'!E16 -> 43555 | G3: ='Data Sheet'!F16 -> 43921 | H3: ='Data Sheet'!G16 -> 44286 | I3: ='Data Sheet'!H16 -> 44651 | J3: ='Data Sheet'!I16 -> 45016 | ... L3: ='Data Sheet'!K16 -> 45747 | M3: LTM
A4: # | B4: Income Statement
B5: Sales | C5: =IFERROR('Data Sheet'!B17,0) -> 273045.6 | D5: =IFERROR('Data Sheet'!C17,0) -> 269692.51 | E5: =IFERROR('Data Sheet'!D17,0) -> 291550.48 | F5: =IFERROR('Data Sheet'!E17,0) -> 301938.4 | G5: =IFERROR('Data Sheet'!F17,0) -> 261067.97 | H5: =IFERROR('Data Sheet'!G17,0) -> 249794.75 | I5: =IFERROR('Data Sheet'!H17,0) -> 278453.62 | J5: =IFERROR('Data Sheet'!I17,0) -> 345966.97 | ... L5: =IFERROR('Data Sheet'!K17,0) -> 439695 | M5: =IFERROR(SUM('Data Sheet'!H42:K42),0) -> 437968
B6: Sales Growth | C6: - | D6: =D5/C5-1 -> -0.01228033 | E6: =E5/D5-1 -> 0.081047746 | F6: =F5/E5-1 -> 0.035629919 | G6: =G5/F5-1 -> -0.13536016 | H6: =H5/G5-1 -> -0.043181168 | I6: =I5/H5-1 -> 0.11472967 | J6: =J5/I5-1 -> 0.24245815 | K6: =K5/J5-1 -> 0.25450126 | ... M6: =M5/L5-1 -> -0.0039277226
B8: COGS | C8: =IFERROR(SUM('Data Sheet'!B18,'Data Sheet'!B20:B22)-1*'Data Sheet'!B19,0) -> 205509.07 | D8: =IFERROR(SUM('Data Sheet'!C18,'Data Sheet'!C20:C22)-1*'Data Sheet'!C19,0) -> 205454.24 | E8: =IFERROR(SUM('Data Sheet'!D18,'Data Sheet'!D20:D22)-1*'Data Sheet'!D19,0) -> 228429.83 | F8: =IFERROR(SUM('Data Sheet'!E18,'Data Sheet'!E20:E22)-1*'Data Sheet'!E19,0) -> 242845.53 | G8: =IFERROR(SUM('Data Sheet'!F18,'Data Sheet'!F20:F22)-1*'Data Sheet'!F19,0) -> 210376.07 | H8: =IFERROR(SUM('Data Sheet'!G18,'Data Sheet'!G20:G22)-1*'Data Sheet'!G19,0) -> 195326.04 | I8: =IFERROR(SUM('Data Sheet'!H18,'Data Sheet'!H20:H22)-1*'Data Sheet'!H19,0) -> 223300.01 | J8: =IFERROR(SUM('Data Sheet'!I18,'Data Sheet'!I20:I22)-1*'Data Sheet'!I19,0) -> 274403.64 | ... L8: =IFERROR(SUM('Data Sheet'!K18,'Data Sheet'!K20:K22)-1*'Data Sheet'!K19,0) -> 340809 | M8: =IFERROR(SUM('Data Sheet'!H43:K43),0) -> 386344
B9: COGS % Sales | C9: =C8/C5-1 -> -0.24734524 | D9: =D8/D5-1 -> -0.23819078 | E9: =E8/E5-1 -> -0.2164999 | F9: =F8/F5-1 -> -0.19571167 | G9: =G8/G5-1 -> -0.19417127 | H9: =H8/H5-1 -> -0.21805386 | I9: =I8/I5-1 -> -0.19807108 | J9: =J8/J5-1 -> -0.20685018 | ... L9: =L8/L5-1 -> -0.2248968 | M9: -
B11: Gross Margin | C11: =C5-C8 -> 67536.53 | D11: =D5-D8 -> 64238.27 | E11: =E5-E8 -> 63120.65 | F11: =F5-F8 -> 59092.87 | G11: =G5-G8 -> 50691.9 | H11: =H5-H8 -> 54468.71 | I11: =I5-I8 -> 55153.61 | J11: =J5-J8 -> 71563.33 | ... M11: =M5-M8 -> 51624
B12: Gross Margin % Sales | C12: =C11/C5 -> 0.24734524 | D12: =D11/D5 -> 0.23819078 | E12: =E11/E5 -> 0.2164999 | F12: =F11/F5 -> 0.19571167 | G12: =G11/G5 -> 0.19417127 | H12: =H11/H5 -> 0.21805386 | I12: =I11/I5 -> 0.19807108 | J12: =J11/J5 -> 0.20685018 | ... M12: =M11/M5 -> 0.11787163
B14: Selling And General Expenses | C14: =IFERROR(SUM('Data Sheet'!B23:B24),0) -> 29141.28 | D14: =IFERROR(SUM('Data Sheet'!C23:C24),0) -> 34649.58 | E14: =IFERROR(SUM('Data Sheet'!D23:D24),0) -> 31662.97 | F14: =IFERROR(SUM('Data Sheet'!E23:E24),0) -> 34428.54 | G14: =IFERROR(SUM('Data Sheet'!F23:F24),0) -> 32704.83 | H14: =IFERROR(SUM('Data Sheet'!G23:G24),0) -> 22181.28 | I14: =IFERROR(SUM('Data Sheet'!H23:H24),0) -> 30433.52 | J14: =IFERROR(SUM('Data Sheet'!I23:I24),0) -> 39747.53 | ... M14: =IFERROR(SUM('Data Sheet'!L23:L24),0) -> 0
B15: S&G Exp % | C15: =C14/C5 -> 0.10672679 | D15: =D14/D5 -> 0.1284781 | E15: =E14/E5 -> 0.10860202 | F15: =F14/F5 -> 0.11402505 | G15: =G14/G5 -> 0.12527324 | H15: =H14/H5 -> 0.088798023 | I15: =I14/I5 -> 0.10929475 | J15: =J14/J5 -> 0.11488822 | ... M15: =M14/M5 -> 0
B17: EBITDA | C17: =C11-C14 -> 38395.25 | D17: =D11-D14 -> 29588.69 | E17: =E11-E14 -> 31457.68 | F17: =F11-F14 -> 24664.33 | G17: =G11-G14 -> 17987.07 | H17: =H11-H14 -> 32287.43 | I17: =I11-I14 -> 24720.09 | J17: =J11-J14 -> 31815.8 | ... M17: =M11-M14 -> 51624
B18: EBITDA % Sales | C18: =C17/C5 -> 0.14061845 | D18: =D17/D5 -> 0.10971269 | E18: =E17/E5 -> 0.10789788 | F18: =F17/F5 -> 0.081686629 | G18: =G17/G5 -> 0.068898034 | H18: =H17/H5 -> 0.12925584 | I18: =I17/I5 -> 0.088776328 | J18: =J17/J5 -> 0.091961958 | ... M18: =M17/M5 -> 0.11787163
B20: Depreciation | C20: =IFERROR('Data Sheet'!B26,0) -> 16710.78 | D20: =IFERROR(SUM('Data Sheet'!C26),0) -> 17904.99 | E20: =IFERROR(SUM('Data Sheet'!D26),0) -> 21553.59 | F20: =IFERROR(SUM('Data Sheet'!E26),0) -> 23590.63 | G20: =IFERROR(SUM('Data Sheet'!F26),0) -> 21425.43 | H20: =IFERROR(SUM('Data Sheet'!G26),0) -> 23546.71 | I20: =IFERROR(SUM('Data Sheet'!H26),0) -> 24835.69 | J20: =IFERROR(SUM('Data Sheet'!I26),0) -> 24860.36 | K20: =IFERROR(SUM('Data Sheet'!J26),0) -> 27239 | ... M20: =IFERROR(SUM('Data Sheet'!L26),0) -> 0
B21: Depreciation % Sales | C21: =C20/C5 -> 0.061201426 | D21: =D20/D5 -> 0.066390387 | E21: =E20/E5 -> 0.073927472 | F21: =F20/F5 -> 0.078130605 | G21: =G20/G5 -> 0.082068398 | H21: =H20/H5 -> 0.094264231 | I21: =I20/I5 -> 0.089191478 | J21: =J20/J5 -> 0.071857611 | ... M21: =M20/M5 -> 0
B23: EBIT | C23: =IFERROR(C17-C20,0) -> 21684.47 | D23: =IFERROR(D17-D20,0) -> 11683.7 | E23: =IFERROR(E17-E20,0) -> 9904.09 | F23: =IFERROR(F17-F20,0) -> 1073.7 | G23: =IFERROR(G17-G20,0) -> -3438.36 | H23: =IFERROR(H17-H20,0) -> 8740.72 | I23: =IFERROR(I17-I20,0) -> -115.6 | J23: =IFERROR(J17-J20,0) -> 6955.44 | ... M23: =IFERROR(M17-M20,0) -> 51624
B24: EBIT % Sales | C24: =IFERROR(C23/C5,0) -> 0.079417028 | D24: =IFERROR(D23/D5,0) -> 0.043322301 | E24: =IFERROR(E23/E5,0) -> 0.033970412 | F24: =IFERROR(F23/F5,0) -> 0.0035560233 | G24: =IFERROR(G23/G5,0) -> -0.013170363 | H24: =IFERROR(H23/H5,0) -> 0.034991608 | I24: =IFERROR(I23/I5,0) -> -0.00041514993 | J24: =IFERROR(J23/J5,0) -> 0.020104347 | ... M24: =IFERROR(M23/M5,0) -> 0.11787163
B26: Intrest | C26: =IFERROR(SUM('Data Sheet'!B27),0) -> 4889.08 | D26: =IFERROR(SUM('Data Sheet'!C27),0) -> 4238.01 | E26: =IFERROR(SUM('Data Sheet'!D27),0) -> 4681.79 | F26: =IFERROR(SUM('Data Sheet'!E27),0) -> 5758.6 | G26: =IFERROR(SUM('Data Sheet'!F27),0) -> 7243.33 | H26: =IFERROR(SUM('Data Sheet'!G27),0) -> 8097.17 | I26: =IFERROR(SUM('Data Sheet'!H27),0) -> 9311.86 | J26: =IFERROR(SUM('Data Sheet'!I27),0) -> 10225.48 | ... M26: =IFERROR(SUM('Data Sheet'!L27),0) -> 0
B27: Intrest % Sales | C27: =C26/C5 -> 0.017905727 | D27: =D26/D5 -> 0.01571423 | E27: =E26/E5 -> 0.016058248 | F27: =F26/F5 -> 0.019072102 | G27: =G26/G5 -> 0.027744997 | H27: =H26/H5 -> 0.032415293 | I27: =I26/I5 -> 0.033441332 | J27: =J26/J5 -> 0.029556232 | ... M27: =M26/M5 -> 0
B29: Earning Before Tax | C29: =C17-(C26+C20) -> 16795.39 | D29: =D17-(D26+D20) -> 7445.69 | E29: =E17-(E26+E20) -> 5222.3 | F29: =F17-(F26+F20) -> -4684.9 | G29: =G17-(G26+G20) -> -10681.69 | H29: =H17-(H26+H20) -> 643.55 | I29: =I17-(I26+I20) -> -9427.46 | J29: =J17-(J26+J20) -> -3270.04 | ... M29: =M17-(M26+M20) -> 51624
B30: EBT % Sales | C30: =C29/C5 -> 0.061511301 | D30: =D29/D5 -> 0.027608071 | E30: =E29/E5 -> 0.017912164 | F30: =F29/F5 -> -0.015516079 | G30: =G29/G5 -> -0.04091536 | H30: =H29/H5 -> 0.0025763152 | I30: =I29/I5 -> -0.033856482 | J30: =J29/J5 -> -0.009451885 | ... M30: =M29/M5 -> 0.11787163
B32: Tax | C32: =IFERROR('Data Sheet'!B29,0) -> 3025.05 | D32: =IFERROR('Data Sheet'!C29,0) -> 3251.23 | E32: =IFERROR('Data Sheet'!D29,0) -> 4341.93 | F32: =IFERROR('Data Sheet'!E29,0) -> -2437.45 | G32: =IFERROR('Data Sheet'!F29,0) -> 395.25 | H32: =IFERROR('Data Sheet'!G29,0) -> 2541.86 | I32: =IFERROR('Data Sheet'!H29,0) -> 4231.29 | J32: =IFERROR('Data Sheet'!I29,0) -> 704.06 | ... M32: =IFERROR('Data Sheet'!L29,0) -> 0
B33: Effective Tax Rate % EBT | C33: =C32/C29 -> 0.18011192 | D33: =D32/D29 -> 0.43665933 | E33: =E32/E29 -> 0.83142102 | F33: =F32/F29 -> 0.52027791 | G33: =G32/G29 -> -0.037002572 | H33: =H32/H29 -> 3.9497475 | I33: =I32/I29 -> -0.44882609 | J33: =J32/J29 -> -0.21530623 | ... M33: =M32/M29 -> 0
B35: Net Profit | C35: =C29-C32 -> 13770.34 | D35: =D29-D32 -> 4194.46 | E35: =E29-E32 -> 880.37 | F35: =F29-F32 -> -2247.45 | G35: =G29-G32 -> -11076.94 | H35: =H29-H32 -> -1898.31 | I35: =I29-I32 -> -13658.75 | J35: =J29-J32 -> -3974.1 | ... M35: =M29-M32 -> 51624
B36: Net Margin | C36: =C35/C5 -> 0.050432382 | D36: =D35/D5 -> 0.015552749 | E36: =E35/E5 -> 0.0030196143 | F36: =F35/F5 -> -0.0074434057 | G36: =G35/G5 -> -0.042429334 | H36: =H35/H5 -> -0.0075994792 | I36: =I35/I5 -> -0.049052155 | J36: =J35/J5 -> -0.011486935 | ... M36: =M35/M5 -> 0.11787163
B38: No. Equity Share Holders | C38: =IFERROR('Data Sheet'!B93,0) -> 288.72 | D38: =IFERROR('Data Sheet'!C93,0) -> 288.73 | E38: =IFERROR('Data Sheet'!D93,0) -> 288.73 | F38: =IFERROR('Data Sheet'!E93,0) -> 288.73 | G38: =IFERROR('Data Sheet'!F93,0) -> 308.9 | H38: =IFERROR('Data Sheet'!G93,0) -> 332.03 | I38: =IFERROR('Data Sheet'!H93,0) -> 332.07 | J38: =IFERROR('Data Sheet'!I93,0) -> 332.13 | ... M38: =IFERROR('Data Sheet'!L93,0) -> 0
B39: Earning per share | C39: =C35/C38 -> 47.694444 | D39: =D35/D38 -> 14.527275 | E39: =E35/E38 -> 3.0491116 | F39: =F35/F38 -> -7.7839158 | G39: =G35/G38 -> -35.859307 | H39: =H35/H38 -> -5.7172846 | I39: =I35/I38 -> -41.132141 | J39: =J35/J38 -> -11.965495 | ... M39: =M35/M38 -> #DIV/0!
B41: Dividend Per Share | C41: =IFERROR('Data Sheet'!B31/'Financials>'!C38,0) -> 0.23524522 | D41: =IFERROR('Data Sheet'!C31/'Financials>'!D38,0) -> 0 | E41: =IFERROR('Data Sheet'!D31/'Financials>'!E37,0) -> 0 | F41: =IFERROR('Data Sheet'!E31/'Financials>'!F38,0) -> 0 | G41: =IFERROR('Data Sheet'!F31/'Financials>'!G38,0) -> 0 | H41: =IFERROR('Data Sheet'!G31/'Financials>'!H38,0) -> 0 | I41: =IFERROR('Data Sheet'!H31/'Financials>'!I38,0) -> 0 | J41: =IFERROR('Data Sheet'!I31/'Financials>'!J38,0) -> 2.3063861 | K41: =IFERROR('Data Sheet'!J31/'Financials>'!K38,0) -> 6.9230075 | L41: =IFERROR('Data Sheet'!K31/'Financials>'!L38,0) -> 5.9978812 | M41: =IFERROR('Data Sheet'!L31/'Financials>'!M38,0) -> 0
B42: Dividend Payout Ratio % | C42: =C41/C38 -> 0.00081478671 | D42: =D41/D38 -> 0 | E42: =E41/E38 -> 0 | F42: =F41/F38 -> 0 | G42: =G41/G38 -> 0 | H42: =H41/H38 -> 0 | I42: =I41/I38 -> 0 | J42: =J41/J38 -> 0.0069442268 | ... M42: =M41/M38 -> #DIV/0!
B44: Retained Earning | C44: =IFERROR(IF(C39>C41,1-C42,0),0) -> 0.99918521 | D44: =IFERROR(IF(D39>D41,1-D42,0),0) -> 1 | E44: =IFERROR(IF(E39>E41,1-E42,0),0) -> 1 | F44: =IFERROR(IF(F39>F41,1-F42,0),0) -> 0 | G44: =IFERROR(IF(G39>G41,1-G42,0),0) -> 0 | H44: =IFERROR(IF(H39>H41,1-H42,0),0) -> 0 | I44: =IFERROR(IF(I39>I41,1-I42,0),0) -> 0 | J44: =IFERROR(IF(J39>J41,1-J42,0),0) -> 0 | ... M44: =IFERROR(IF(M39>M41,1-M42,0),0) -> 0
A46: # | B46: Balance Sheet
B47: Equity Share Capitals | C47: =IFERROR('Data Sheet'!B57,0) -> 679.18 | D47: =IFERROR('Data Sheet'!C57,0) -> 679.22 | E47: =IFERROR('Data Sheet'!D57,0) -> 679.22 | F47: =IFERROR('Data Sheet'!E57,0) -> 679.22 | G47: =IFERROR('Data Sheet'!F57,0) -> 719.54 | H47: =IFERROR('Data Sheet'!G57,0) -> 765.81 | I47: =IFERROR('Data Sheet'!H57,0) -> 765.88 | J47: =IFERROR('Data Sheet'!I57,0) -> 766.02 | ... M47: =IFERROR('Data Sheet'!L57,0) -> 0
B48: Reserves | C48: =IFERROR('Data Sheet'!B58,0) -> 78273.23 | D48: =IFERROR('Data Sheet'!C58,0) -> 57382.67 | E48: =IFERROR('Data Sheet'!D58,0) -> 94748.69 | F48: =IFERROR('Data Sheet'!E58,0) -> 59500.34 | G48: =IFERROR('Data Sheet'!F58,0) -> 62358.99 | H48: =IFERROR('Data Sheet'!G58,0) -> 54480.91 | I48: =IFERROR('Data Sheet'!H58,0) -> 43795.36 | J48: =IFERROR('Data Sheet'!I58,0) -> 44555.77 | ... M48: =IFERROR('Data Sheet'!L58,0) -> 0
B49: Borrowings | C49: =IFERROR('Data Sheet'!B59,0) -> 69359.96 | D49: =IFERROR('Data Sheet'!C59,0) -> 78603.98 | E49: =IFERROR('Data Sheet'!D59,0) -> 88950.47 | F49: =IFERROR('Data Sheet'!E59,0) -> 106175.34 | G49: =IFERROR('Data Sheet'!F59,0) -> 124787.64 | H49: =IFERROR('Data Sheet'!G59,0) -> 142130.57 | I49: =IFERROR('Data Sheet'!H59,0) -> 146449.03 | J49: =IFERROR('Data Sheet'!I59,0) -> 134113.44 | ... M49: =IFERROR('Data Sheet'!L59,0) -> 0
B50: Other Liabilities | C50: =IFERROR('Data Sheet'!B60,0) -> 114871.75 | D50: =IFERROR('Data Sheet'!C60,0) -> 135914.49 | E50: =IFERROR('Data Sheet'!D60,0) -> 142813.43 | F50: =IFERROR('Data Sheet'!E60,0) -> 139348.59 | G50: =IFERROR('Data Sheet'!F60,0) -> 132313.22 | H50: =IFERROR('Data Sheet'!G60,0) -> 144192.62 | I50: =IFERROR('Data Sheet'!H60,0) -> 138051.22 | J50: =IFERROR('Data Sheet'!I60,0) -> 155239.2 | ... M50: =IFERROR('Data Sheet'!L60,0) -> 0
B51: Total Liabilities | C51: =IFERROR('Data Sheet'!B61,0) -> 263184.12 | D51: =IFERROR('Data Sheet'!C61,0) -> 272580.36 | E51: =IFERROR('Data Sheet'!D61,0) -> 327191.81 | F51: =IFERROR('Data Sheet'!E61,0) -> 305703.49 | G51: =IFERROR('Data Sheet'!F61,0) -> 320179.39 | H51: =IFERROR('Data Sheet'!G61,0) -> 341569.91 | I51: =IFERROR('Data Sheet'!H61,0) -> 329061.49 | J51: =IFERROR('Data Sheet'!I61,0) -> 334674.43 | ... M51: =IFERROR('Data Sheet'!L61,0) -> 0
B53: Net Block | C53: =IFERROR('Data Sheet'!B62,0) -> 107231.76 | D53: =IFERROR('Data Sheet'!C62,0) -> 95944.08 | E53: =IFERROR('Data Sheet'!D62,0) -> 121413.86 | F53: =IFERROR('Data Sheet'!E62,0) -> 111234.47 | G53: =IFERROR('Data Sheet'!F62,0) -> 127107.14 | H53: =IFERROR('Data Sheet'!G62,0) -> 138707.61 | I53: =IFERROR('Data Sheet'!H62,0) -> 138855.45 | J53: =IFERROR('Data Sheet'!I62,0) -> 132079.76 | ... M53: =IFERROR('Data Sheet'!L62,0) -> 0
B54: Capital Work in Progress | C54: =IFERROR('Data Sheet'!B63,0) -> 25918.94 | D54: =IFERROR('Data Sheet'!C63,0) -> 33698.84 | E54: =IFERROR('Data Sheet'!D63,0) -> 40033.5 | F54: =IFERROR('Data Sheet'!E63,0) -> 31883.84 | G54: =IFERROR('Data Sheet'!F63,0) -> 35622.29 | H54: =IFERROR('Data Sheet'!G63,0) -> 20963.93 | I54: =IFERROR('Data Sheet'!H63,0) -> 10251.09 | J54: =IFERROR('Data Sheet'!I63,0) -> 14274.5 | ... M54: =IFERROR('Data Sheet'!L63,0) -> 0
B55: Investments | C55: =IFERROR('Data Sheet'!B64,0) -> 23767.02 | D55: =IFERROR('Data Sheet'!C64,0) -> 20337.92 | E55: =IFERROR('Data Sheet'!D64,0) -> 20812.75 | F55: =IFERROR('Data Sheet'!E64,0) -> 15770.72 | G55: =IFERROR('Data Sheet'!F64,0) -> 16308.48 | H55: =IFERROR('Data Sheet'!G64,0) -> 24620.28 | I55: =IFERROR('Data Sheet'!H64,0) -> 29379.53 | J55: =IFERROR('Data Sheet'!I64,0) -> 26379.16 | ... M55: =IFERROR('Data Sheet'!L64,0) -> 0
B56: Other Assets | C56: =IFERROR('Data Sheet'!B65,0) -> 106266.4 | D56: =IFERROR('Data Sheet'!C65,0) -> 122599.52 | E56: =IFERROR('Data Sheet'!D65,0) -> 144931.7 | F56: =IFERROR('Data Sheet'!E65,0) -> 146814.46 | G56: =IFERROR('Data Sheet'!F65,0) -> 141141.48 | H56: =IFERROR('Data Sheet'!G65,0) -> 157278.09 | I56: =IFERROR('Data Sheet'!H65,0) -> 150575.42 | J56: =IFERROR('Data Sheet'!I65,0) -> 161941.01 | ... M56: =IFERROR('Data Sheet'!L65,0) -> 0
...

Sheet Ratio Analysis
B2: ="Ratio Analysis - "&'Data Sheet'!B1 -> Ratio Analysis - TATA MOTORS PASSENGER VEHICLES LTD
B3: Years | C3: ='Data Sheet'!B16 -> 42460 | D3: ='Data Sheet'!C16 -> 42825 | E3: ='Data Sheet'!D16 -> 43190 | F3: ='Data Sheet'!E16 -> 43555 | G3: ='Data Sheet'!F16 -> 43921 | H3: ='Data Sheet'!G16 -> 44286 | I3: ='Data Sheet'!H16 -> 44651 | J3: ='Data Sheet'!I16 -> 45016 | ... L3: ='Data Sheet'!K16 -> 45747 | M3: Trend | N3: Mean | O3: Median
B5: Sales Growth | C5: - | D5: =IFERROR('Financials>'!D6,0) -> -0.01228033 | E5: =IFERROR('Financials>'!E6,0) -> 0.081047746 | F5: =IFERROR('Financials>'!F6,0) -> 0.035629919 | G5: =IFERROR('Financials>'!G6,0) -> -0.13536016 | H5: =IFERROR('Financials>'!H6,0) -> -0.043181168 | I5: =IFERROR('Financials>'!I6,0) -> 0.11472967 | J5: =IFERROR('Financials>'!J6,0) -> 0.24245815 | K5: =IFERROR('Financials>'!K6,0) -> 0.25450126 | L5: =IFERROR('Financials>'!L6,0) -> 0.013084771 | N5: =IFERROR(AVERAGE(D5:L5),0) -> 0.061181096 | O5: =IFERROR(MEDIAN(D5:L5),0) -> 0.035629919
B6: EBITDA Growth | C6: - | D6: =IFERROR(('Financials>'!C17-'Financials>'!D17)/'Financials>'!C17,0) -> 0.22936587 | E6: =IFERROR(('Financials>'!D17-'Financials>'!E17)/'Financials>'!D17,0) -> -0.063165689 | F6: =IFERROR(('Financials>'!E17-'Financials>'!F17)/'Financials>'!E17,0) -> 0.21595203 | G6: =IFERROR(('Financials>'!F17-'Financials>'!G17)/'Financials>'!F17,0) -> 0.27072538 | H6: =IFERROR(('Financials>'!G17-'Financials>'!H17)/'Financials>'!G17,0) -> -0.79503554 | I6: =IFERROR(('Financials>'!H17-'Financials>'!I17)/'Financials>'!H17,0) -> 0.23437418 | J6: =IFERROR(('Financials>'!I17-'Financials>'!J17)/'Financials>'!I17,0) -> -0.28704224 | K6: =IFERROR(('Financials>'!J17-'Financials>'!K17)/'Financials>'!J17,0) -> -0.81746176 | L6: =IFERROR(('Financials>'!K17-'Financials>'!L17)/'Financials>'!K17,0) -> 0.04510238 | N6: =IFERROR(AVERAGE(D6:L6),0) -> -0.10746504 | O6: =IFERROR(MEDIAN(D6:L6),0) -> 0.04510238
B7: EBIT Growth | C7: - | D7: =IFERROR(('Financials>'!D23-'Financials>'!C23)/'Financials>'!C23,0) -> -0.46119504 | E7: =IFERROR(('Financials>'!E23-'Financials>'!D23)/'Financials>'!D23,0) -> -0.15231562 | F7: =IFERROR(('Financials>'!F23-'Financials>'!E23)/'Financials>'!E23,0) -> -0.89159024 | G7: =IFERROR(('Financials>'!G23-'Financials>'!F23)/'Financials>'!F23,0) -> -4.202347 | H7: =IFERROR(('Financials>'!H23-'Financials>'!G23)/'Financials>'!G23,0) -> -3.5421189 | I7: =IFERROR(('Financials>'!I23-'Financials>'!H23)/'Financials>'!H23,0) -> -1.0132255 | J7: =IFERROR(('Financials>'!J23-'Financials>'!I23)/'Financials>'!I23,0) -> -61.168166 | K7: =IFERROR(('Financials>'!K23-'Financials>'!J23)/'Financials>'!J23,0) -> 3.3972775 | L7: =IFERROR(('Financials>'!L23-'Financials>'!K23)/'Financials>'!K23,0) -> 0.044956678 | N7: =IFERROR(AVERAGE(D7:L7),0) -> -7.5543027 | O7: =IFERROR(MEDIAN(D7:L7),0) -> -0.89159024
B8: Net Profit Growth | C8: - | D8: =IFERROR(('Financials>'!D35-'Financials>'!C35)/'Financials>'!C35,0) -> -0.69539895 | E8: =IFERROR(('Financials>'!E35-'Financials>'!D35)/'Financials>'!D35,0) -> -0.79011124 | F8: =IFERROR(('Financials>'!F35-'Financials>'!E35)/'Financials>'!E35,0) -> -3.5528471 | G8: =IFERROR(('Financials>'!G35-'Financials>'!F35)/'Financials>'!F35,0) -> 3.9286703 | H8: =IFERROR(('Financials>'!H35-'Financials>'!G35)/'Financials>'!G35,0) -> -0.82862505 | I8: =IFERROR(('Financials>'!I35-'Financials>'!H35)/'Financials>'!H35,0) -> 6.1952157 | J8: =IFERROR(('Financials>'!J35-'Financials>'!I35)/'Financials>'!I35,0) -> -0.70904365 | K8: =IFERROR(('Financials>'!K35-'Financials>'!J35)/'Financials>'!J35,0) -> -7.7977655 | L8: =IFERROR(('Financials>'!L35-'Financials>'!K35)/'Financials>'!K35,0) -> -0.39385527 | N8: =IFERROR(AVERAGE(D8:L8),0) -> -0.51597342 | O8: =IFERROR(MEDIAN(D8:L8),0) -> -0.70904365
B9: Dividend Growth | C9: - | D9: =IFERROR('Financials>'!E41/'Financials>'!D41-1,0) -> 0 | E9: =IFERROR('Financials>'!F41/'Financials>'!E41-1,0) -> 0 | F9: =IFERROR('Financials>'!G41/'Financials>'!F41-1,0) -> 0 | G9: =IFERROR('Financials>'!H41/'Financials>'!G41-1,0) -> 0 | H9: =IFERROR('Financials>'!I41/'Financials>'!H41-1,0) -> 0 | I9: =IFERROR('Financials>'!J41/'Financials>'!I41-1,0) -> 0 | J9: =IFERROR('Financials>'!K41/'Financials>'!J41-1,0) -> 2.001669 | K9: =IFERROR('Financials>'!L41/'Financials>'!K41-1,0) -> -0.1336307 | L9: =IFERROR('Financials>'!M41/'Financials>'!L41-1,0) -> -1 | N9: =IFERROR(AVERAGE(D9:L9),0) -> 0.096448699 | O9: =IFERROR(MEDIAN(D9:L9),0) -> 0
B11: Gross Margin | C11: =IFERROR('Financials>'!C12,0) -> 0.24734524 | D11: =IFERROR('Financials>'!D12,0) -> 0.23819078 | E11: =IFERROR('Financials>'!E12,0) -> 0.2164999 | F11: =IFERROR('Financials>'!F12,0) -> 0.19571167 | G11: =IFERROR('Financials>'!G12,0) -> 0.19417127 | H11: =IFERROR('Financials>'!H12,0) -> 0.21805386 | I11: =IFERROR('Financials>'!I12,0) -> 0.19807108 | J11: =IFERROR('Financials>'!J12,0) -> 0.20685018 | ... L11: =IFERROR('Financials>'!L12,0) -> 0.2248968 | N11: =IFERROR(AVERAGE(C11:L11),0) -> 0.21693584 | O11: =IFERROR(MEDIAN(C11:L11),0) -> 0.21727688
B12: Oprations Margin | C12: =IFERROR('Financials>'!C18,0) -> 0.14061845 | D12: =IFERROR('Financials>'!D18,0) -> 0.10971269 | E12: =IFERROR('Financials>'!E18,0) -> 0.10789788 | F12: =IFERROR('Financials>'!F18,0) -> 0.081686629 | G12: =IFERROR('Financials>'!G18,0) -> 0.068898034 | H12: =IFERROR('Financials>'!H18,0) -> 0.12925584 | I12: =IFERROR('Financials>'!I18,0) -> 0.088776328 | J12: =IFERROR('Financials>'!J18,0) -> 0.091961958 | ... L12: =IFERROR('Financials>'!L18,0) -> 0.12557796 | N12: =IFERROR(AVERAGE(C12:L12),0) -> 0.10776159 | O12: =IFERROR(MEDIAN(C12:L12),0) -> 0.10880529
B13: EBITDA Margin | C13: =IFERROR('Financials>'!C18,0) -> 0.14061845 | D13: =IFERROR('Financials>'!D18,0) -> 0.10971269 | E13: =IFERROR('Financials>'!E18,0) -> 0.10789788 | F13: =IFERROR('Financials>'!F18,0) -> 0.081686629 | G13: =IFERROR('Financials>'!G18,0) -> 0.068898034 | H13: =IFERROR('Financials>'!H18,0) -> 0.12925584 | I13: =IFERROR('Financials>'!I18,0) -> 0.088776328 | J13: =IFERROR('Financials>'!J18,0) -> 0.091961958 | ... L13: =IFERROR('Financials>'!L18,0) -> 0.12557796 | N13: =IFERROR(AVERAGE(C13:L13),0) -> 0.10776159 | O13: =IFERROR(MEDIAN(C13:L13),0) -> 0.10880529
B14: EBIT Margin | C14: =IFERROR('Financials>'!C24,0) -> 0.079417028 | D14: =IFERROR('Financials>'!D24,0) -> 0.043322301 | E14: =IFERROR('Financials>'!E24,0) -> 0.033970412 | F14: =IFERROR('Financials>'!F24,0) -> 0.0035560233 | G14: =IFERROR('Financials>'!G24,0) -> -0.013170363 | H14: =IFERROR('Financials>'!H24,0) -> 0.034991608 | I14: =IFERROR('Financials>'!I24,0) -> -0.00041514993 | J14: =IFERROR('Financials>'!J24,0) -> 0.020104347 | ... L14: =IFERROR('Financials>'!L24,0) -> 0.072686749 | N14: =IFERROR(AVERAGE(C14:L14),0) -> 0.034493271 | O14: =IFERROR(MEDIAN(C14:L14),0) -> 0.03448101
B15: EBT Margin | C15: =IFERROR('Financials>'!C30,0) -> 0.061511301 | D15: =IFERROR('Financials>'!D30,0) -> 0.027608071 | E15: =IFERROR('Financials>'!E30,0) -> 0.017912164 | F15: =IFERROR('Financials>'!F30,0) -> -0.015516079 | G15: =IFERROR('Financials>'!G30,0) -> -0.04091536 | H15: =IFERROR('Financials>'!H30,0) -> 0.0025763152 | I15: =IFERROR('Financials>'!I30,0) -> -0.033856482 | J15: =IFERROR('Financials>'!J30,0) -> -0.009451885 | ... L15: =IFERROR('Financials>'!L30,0) -> 0.061126463 | N15: =IFERROR(AVERAGE(C15:L15),0) -> 0.012396721 | O15: =IFERROR(MEDIAN(C15:L15),0) -> 0.01024424
B16: Net Profit Margin | C16: =IFERROR('Financials>'!C36,0) -> 0.050432382 | D16: =IFERROR('Financials>'!D36,0) -> 0.015552749 | E16: =IFERROR('Financials>'!E36,0) -> 0.0030196143 | F16: =IFERROR('Financials>'!F36,0) -> -0.0074434057 | G16: =IFERROR('Financials>'!G36,0) -> -0.042429334 | H16: =IFERROR('Financials>'!H36,0) -> -0.0075994792 | I16: =IFERROR('Financials>'!I36,0) -> -0.049052155 | J16: =IFERROR('Financials>'!J36,0) -> -0.011486935 | ... L16: =IFERROR('Financials>'!L36,0) -> 0.037241724 | N16: =IFERROR(AVERAGE(C16:L16),0) -> 0.0050479411 | O16: =IFERROR(MEDIAN(C16:L16),0) -> -0.0022118957
B18: Sales Expenses%Sales | C18: =IFERROR('Financials>'!C15,0) -> 0.10672679 | D18: =IFERROR('Financials>'!D15,0) -> 0.1284781 | E18: =IFERROR('Financials>'!E15,0) -> 0.10860202 | F18: =IFERROR('Financials>'!F15,0) -> 0.11402505 | G18: =IFERROR('Financials>'!G15,0) -> 0.12527324 | H18: =IFERROR('Financials>'!H15,0) -> 0.088798023 | I18: =IFERROR('Financials>'!I15,0) -> 0.10929475 | J18: =IFERROR('Financials>'!J15,0) -> 0.11488822 | ... L18: =IFERROR('Financials>'!L15,0) -> 0.099318846 | N18: =IFERROR(AVERAGE(C18:L18),0) -> 0.10917425 | O18: =IFERROR(MEDIAN(C18:L18),0) -> 0.10894839
B19: Depreciation%Sales | C19: =IFERROR('Financials>'!C21,0) -> 0.061201426 | D19: =IFERROR('Financials>'!D21,0) -> 0.066390387 | E19: =IFERROR('Financials>'!E21,0) -> 0.073927472 | F19: =IFERROR('Financials>'!F21,0) -> 0.078130605 | G19: =IFERROR('Financials>'!G21,0) -> 0.082068398 | H19: =IFERROR('Financials>'!H21,0) -> 0.094264231 | I19: =IFERROR('Financials>'!I21,0) -> 0.089191478 | J19: =IFERROR('Financials>'!J21,0) -> 0.071857611 | ... L19: =IFERROR('Financials>'!L21,0) -> 0.052891209 | N19: =IFERROR(AVERAGE(C19:L19),0) -> 0.073268318 | O19: =IFERROR(MEDIAN(C19:L19),0) -> 0.072892542
B20: OperatingIncome%Sales | C20: =C14 -> 0.079417028 | D20: =D14 -> 0.043322301 | E20: =E14 -> 0.033970412 | F20: =F14 -> 0.0035560233 | G20: =G14 -> -0.013170363 | H20: =H14 -> 0.034991608 | I20: =I14 -> -0.00041514993 | J20: =J14 -> 0.020104347 | ... L20: =L14 -> 0.072686749 | N20: =IFERROR(AVERAGE(C20:L20),0) -> 0.034493271 | O20: =IFERROR(MEDIAN(C20:L20),0) -> 0.03448101
B22: Return on Capital Employed | C22: =IFERROR('Financials>'!C23/(SUM('Financials>'!C47:C49)),0) -> 0.1462081 | D22: =IFERROR('Financials>'!D23/(SUM('Financials>'!D47:D49)),0) -> 0.085490986 | E22: =IFERROR('Financials>'!E23/(SUM('Financials>'!E47:E49)),0) -> 0.053716114 | F22: =IFERROR('Financials>'!F23/(SUM('Financials>'!F47:F49)),0) -> 0.0064542734 | G22: =IFERROR('Financials>'!G23/(SUM('Financials>'!G47:G49)),0) -> -0.018302178 | H22: =IFERROR('Financials>'!H23/(SUM('Financials>'!H47:H49)),0) -> 0.044284325 | I22: =IFERROR('Financials>'!I23/(SUM('Financials>'!I47:I49)),0) -> -0.00060520306 | J22: =IFERROR('Financials>'!J23/(SUM('Financials>'!J47:J49)),0) -> 0.038762956 | ... L22: =IFERROR('Financials>'!L23/(SUM('Financials>'!L47:L49)),0) -> 0.17028623 | N22: =IFERROR(AVERAGE(C22:L22),0) -> 0.068544162 | O22: =IFERROR(MEDIAN(C22:L22),0) -> 0.049000219
B23: Retained Earnings% | C23: =IFERROR('Financials>'!C44,0) -> 0.99918521 | D23: =IFERROR('Financials>'!D44,0) -> 1 | E23: =IFERROR('Financials>'!E44,0) -> 1 | F23: =IFERROR('Financials>'!F44,0) -> 0 | G23: =IFERROR('Financials>'!G44,0) -> 0 | H23: =IFERROR('Financials>'!H44,0) -> 0 | I23: =IFERROR('Financials>'!I44,0) -> 0 | J23: =IFERROR('Financials>'!J44,0) -> 0 | ... L23: =IFERROR('Financials>'!L44,0) -> 0.98370717 | N23: =IFERROR(AVERAGE(C23:L23),0) -> 0.49620632 | O23: =IFERROR(MEDIAN(C23:L23),0) -> 0.48958539
B24: Return on Equity% | C24: =IFERROR('Financials>'!C35/SUM('Financials>'!C47:C48),0) -> 0.17441317 | D24: =IFERROR('Financials>'!D35/SUM('Financials>'!D47:D48),0) -> 0.07224119 | E24: =IFERROR('Financials>'!E35/SUM('Financials>'!E47:E48),0) -> 0.0092254981 | F24: =IFERROR('Financials>'!F35/SUM('Financials>'!F47:F48),0) -> -0.037345737 | G24: =IFERROR('Financials>'!G35/SUM('Financials>'!G47:G48),0) -> -0.17560555 | H24: =IFERROR('Financials>'!H35/SUM('Financials>'!H47:H48),0) -> -0.034360592 | I24: =IFERROR('Financials>'!I35/SUM('Financials>'!I47:I48),0) -> -0.30651638 | J24: =IFERROR('Financials>'!J35/SUM('Financials>'!J47:J48),0) -> -0.087686298 | ... L24: =IFERROR('Financials>'!L35/SUM('Financials>'!L47:L48),0) -> 0.14098877 | N24: =IFERROR(AVERAGE(C24:L24),0) -> 0.0073484502 | O24: =IFERROR(MEDIAN(C24:L24),0) -> -0.012567547
B25: Self Sustained Growth Rate | C25: =IFERROR(C24*C23,0) -> 0.17427106 | D25: =IFERROR(D24*D23,0) -> 0.07224119 | E25: =IFERROR(E24*E23,0) -> 0.0092254981 | F25: =IFERROR(F24*F23,0) -> 0 | G25: =IFERROR(G24*G23,0) -> 0 | H25: =IFERROR(H24*H23,0) -> 0 | I25: =IFERROR(I24*I23,0) -> 0 | J25: =IFERROR(J24*J23,0) -> 0 | ... L25: =IFERROR(L24*L23,0) -> 0.13869167 | N25: =IFERROR(AVERAGE(C25:L25),0) -> 0.070593344 | O25: =IFERROR(MEDIAN(C25:L25),0) -> 0.004612749
C26: =IFERROR('Financials>'!C23/'Financials>'!C26,0) -> 4.4352864 | D26: =IFERROR('Financials>'!D23/'Financials>'!D26,0) -> 2.7568835 | E26: =IFERROR('Financials>'!E23/'Financials>'!E26,0) -> 2.1154494 | F26: =IFERROR('Financials>'!F23/'Financials>'!F26,0) -> 0.18645157 | G26: =IFERROR('Financials>'!G23/'Financials>'!G26,0) -> -0.47469327 | H26: =IFERROR('Financials>'!H23/'Financials>'!H26,0) -> 1.0794784 | I26: =IFERROR('Financials>'!I23/'Financials>'!I26,0) -> -0.012414276 | J26: =IFERROR('Financials>'!J23/'Financials>'!J26,0) -> 0.6802067 | ... L26: =IFERROR('Financials>'!L23/'Financials>'!L26,0) -> 6.2876254 | N26: =IFERROR(AVERAGE(C26:L26),0) -> 2.1081796 | O26: =IFERROR(MEDIAN(C26:L26),0) -> 1.5974639
B28: Debtor Turnover Ratio | C28: =IFERROR('Financials>'!C5/'Financials>'!C59,0) -> 20.119918 | D28: =IFERROR('Financials>'!D5/'Financials>'!D59,0) -> 19.160353 | E28: =IFERROR('Financials>'!E5/'Financials>'!E59,0) -> 14.655712 | F28: =IFERROR('Financials>'!F5/'Financials>'!F59,0) -> 15.894699 | G28: =IFERROR('Financials>'!G5/'Financials>'!G59,0) -> 23.366617 | H28: =IFERROR('Financials>'!H5/'Financials>'!H59,0) -> 19.701331 | I28: =IFERROR('Financials>'!I5/'Financials>'!I59,0) -> 22.379918 | J28: =IFERROR('Financials>'!J5/'Financials>'!J59,0) -> 21.982948 | ... L28: =IFERROR('Financials>'!L5/'Financials>'!L59,0) -> 33.189538 | N28: =IFERROR(AVERAGE(C28:L28),0) -> 21.605368 | O28: =IFERROR(MEDIAN(C28:L28),0) -> 21.051433
B29: Creditor Turnover Ratio | C29: =IFERROR('Financials>'!C5/'Financials>'!C50,0) -> 2.3769604 | D29: =IFERROR('Financials>'!D5/'Financials>'!D50,0) -> 1.9842808 | E29: =IFERROR('Financials>'!E5/'Financials>'!E50,0) -> 2.041478 | F29: =IFERROR('Financials>'!F5/'Financials>'!F50,0) -> 2.1667848 | G29: =IFERROR('Financials>'!G5/'Financials>'!G50,0) -> 1.9731057 | H29: =IFERROR('Financials>'!H5/'Financials>'!H50,0) -> 1.7323685 | I29: =IFERROR('Financials>'!I5/'Financials>'!I50,0) -> 2.0170312 | J29: =IFERROR('Financials>'!J5/'Financials>'!J50,0) -> 2.2286057 | ... L29: =IFERROR('Financials>'!L5/'Financials>'!L50,0) -> 2.3228767 | N29: =IFERROR(AVERAGE(C29:L29),0) -> 2.1290872 | O29: =IFERROR(MEDIAN(C29:L29),0) -> 2.1041314
B30: Inventory Turnover | C30: =IFERROR('Financials>'!C8/'Financials>'!C60,0) -> 6.2932009 | D30: =IFERROR('Financials>'!D8/'Financials>'!D60,0) -> 5.8558479 | E30: =IFERROR('Financials>'!E8/'Financials>'!E60,0) -> 5.4210412 | F30: =IFERROR('Financials>'!F8/'Financials>'!F60,0) -> 6.2246171 | G30: =IFERROR('Financials>'!G8/'Financials>'!G60,0) -> 5.6164867 | H30: =IFERROR('Financials>'!H8/'Financials>'!H60,0) -> 5.4124043 | I30: =IFERROR('Financials>'!I8/'Financials>'!I60,0) -> 6.3364885 | J30: =IFERROR('Financials>'!J8/'Financials>'!J60,0) -> 6.7329411 | ... L30: =IFERROR('Financials>'!L8/'Financials>'!L60,0) -> 7.2099896 | N30: =IFERROR(AVERAGE(C30:L30),0) -> 6.2100172 | O30: =IFERROR(MEDIAN(C30:L30),0) -> 6.258909
B31: Fixed Asset Turnover | C31: =IFERROR('Financials>'!C5/'Financials>'!C53,0) -> 2.5463128 | D31: =IFERROR('Financials>'!D5/'Financials>'!D53,0) -> 2.8109343 | E31: =IFERROR('Financials>'!E5/'Financials>'!E53,0) -> 2.4012949 | F31: =IFERROR('Financials>'!F5/'Financials>'!F53,0) -> 2.714432 | G31: =IFERROR('Financials>'!G5/'Financials>'!G53,0) -> 2.0539206 | H31: =IFERROR('Financials>'!H5/'Financials>'!H53,0) -> 1.8008727 | I31: =IFERROR('Financials>'!I5/'Financials>'!I53,0) -> 2.0053489 | J31: =IFERROR('Financials>'!J5/'Financials>'!J53,0) -> 2.6193792 | ... L31: =IFERROR('Financials>'!L5/'Financials>'!L53,0) -> 3.800401 | N31: =IFERROR(AVERAGE(C31:L31),0) -> 2.6331377 | O31: =IFERROR(MEDIAN(C31:L31),0) -> 2.582846
B32: Capital Turnover Ratio | C32: =IFERROR('Financials>'!C5/SUM('Financials>'!C47:C48),0) -> 3.4583567 | D32: =IFERROR('Financials>'!D5/SUM('Financials>'!D47:D48),0) -> 4.6449144 | E32: =IFERROR('Financials>'!E5/SUM('Financials>'!E47:E48),0) -> 3.0551909 | F32: =IFERROR('Financials>'!F5/SUM('Financials>'!F47:F48),0) -> 5.0172916 | G32: =IFERROR('Financials>'!G5/SUM('Financials>'!G47:G48),0) -> 4.138777 | H32: =IFERROR('Financials>'!H5/SUM('Financials>'!H47:H48),0) -> 4.5214404 | I32: =IFERROR('Financials>'!I5/SUM('Financials>'!I47:I48),0) -> 6.2487853 | J32: =IFERROR('Financials>'!J5/SUM('Financials>'!J47:J48),0) -> 7.6335681 | ... L32: =IFERROR('Financials>'!L5/SUM('Financials>'!L47:L48),0) -> 3.7857746 | N32: =IFERROR(AVERAGE(C32:L32),0) -> 4.76151 | O32: =IFERROR(MEDIAN(C32:L32),0) -> 4.5831774
B34: Debtor Days | C34: =IFERROR(365/C28,0) -> 18.141227 | D34: =IFERROR(365/D28,0) -> 19.049753 | E34: =IFERROR(365/E28,0) -> 24.904965 | F34: =IFERROR(365/F28,0) -> 22.963631 | G34: =IFERROR(365/G28,0) -> 15.620575 | H34: =IFERROR(365/H28,0) -> 18.526667 | I34: =IFERROR(365/I28,0) -> 16.309265 | J34: =IFERROR(365/J28,0) -> 16.603779 | ... L34: =IFERROR(365/L28,0) -> 10.997441 | N34: =IFERROR(AVERAGE(C34:L34),0) -> 17.737364 | O34: =IFERROR(MEDIAN(C34:L34),0) -> 17.372503
B35: Payable Days | C35: =IFERROR(365/C29,0) -> 153.55746 | D35: =IFERROR(365/D29,0) -> 183.94574 | E35: =IFERROR(365/E29,0) -> 178.79203 | F35: =IFERROR(365/F29,0) -> 168.45236 | G35: =IFERROR(365/G29,0) -> 184.98755 | H35: =IFERROR(365/H29,0) -> 210.69421 | I35: =IFERROR(365/I29,0) -> 180.95902 | J35: =IFERROR(365/J29,0) -> 163.77953 | ... L35: =IFERROR(365/L29,0) -> 157.13275 | N35: =IFERROR(AVERAGE(C35:L35),0) -> 173.14397 | O35: =IFERROR(MEDIAN(C35:L35),0) -> 173.62219
B36: Inventory Days | C36: =IFERROR(365/C30,0) -> 57.999102 | D36: =IFERROR(365/D30,0) -> 62.330854 | E36: =IFERROR(365/E30,0) -> 67.330239 | F36: =IFERROR(365/F30,0) -> 58.638145 | G36: =IFERROR(365/G30,0) -> 64.987245 | H36: =IFERROR(365/H30,0) -> 67.437682 | I36: =IFERROR(365/I30,0) -> 57.602882 | J36: =IFERROR(365/J30,0) -> 54.211079 | ... L36: =IFERROR(365/L30,0) -> 50.624206 | N36: =IFERROR(AVERAGE(C36:L36),0) -> 59.33255 | O36: =IFERROR(MEDIAN(C36:L36),0) -> 58.318623
B37: Cash Conversion Cycle | C37: =IFERROR(SUM(C36,C34)-C35,0) -> -77.417131 | D37: =IFERROR(SUM(D36,D34)-D35,0) -> -102.56514 | E37: =IFERROR(SUM(E36,E34)-E35,0) -> -86.556826 | F37: =IFERROR(SUM(F36,F34)-F35,0) -> -86.850581 | G37: =IFERROR(SUM(G36,G34)-G35,0) -> -104.37973 | H37: =IFERROR(SUM(H36,H34)-H35,0) -> -124.72986 | I37: =IFERROR(SUM(I36,I34)-I35,0) -> -107.04688 | J37: =IFERROR(SUM(J36,J34)-J35,0) -> -92.964673 | ... L37: =IFERROR(SUM(L36,L34)-L35,0) -> -95.511104 | N37: =IFERROR(AVERAGE(C37:L37),0) -> -96.074056 | O37: =IFERROR(MEDIAN(C37:L37),0) -> -94.237888
B39: CFO/Sales | C39: =IFERROR('Financials>'!C70/'Financials>'!C5,0) -> 0.14146355 | D39: =IFERROR('Financials>'!D70/'Financials>'!D5,0) -> 0.1069366 | E39: =IFERROR('Financials>'!E70/'Financials>'!E5,0) -> 0.11425809 | F39: =IFERROR('Financials>'!F70/'Financials>'!F5,0) -> 0.095287648 | G39: =IFERROR('Financials>'!G70/'Financials>'!G5,0) -> 0.08944797 | H39: =IFERROR('Financials>'!H70/'Financials>'!H5,0) -> 0.12489454 | I39: =IFERROR('Financials>'!I70/'Financials>'!I5,0) -> 0.096759381 | J39: =IFERROR('Financials>'!J70/'Financials>'!J5,0) -> 0.12051439 | ... L39: =IFERROR('Financials>'!L70/'Financials>'!L5,0) -> 0.13404064 | N39: =IFERROR(AVERAGE(C39:L39),0) -> 0.11736111 | O39: =IFERROR(MEDIAN(C39:L39),0) -> 0.11738624
B40: CFO/Total Assets | C40: =IFERROR('Financials>'!C77/'Financials>'!C64,0) -> 0.14400185 | D40: =IFERROR('Financials>'!D77/'Financials>'!D64,0) -> 0.11079302 | E40: =IFERROR('Financials>'!E77/'Financials>'!E64,0) -> 0.072914417 | F40: =IFERROR('Financials>'!F77/'Financials>'!F64,0) -> 0.061798444 | G40: =IFERROR('Financials>'!G77/'Financials>'!G64,0) -> 0.083181494 | H40: =IFERROR('Financials>'!H77/'Financials>'!H64,0) -> 0.084902092 | I40: =IFERROR('Financials>'!I77/'Financials>'!I64,0) -> 0.043402222 | J40: =IFERROR('Financials>'!J77/'Financials>'!J64,0) -> 0.10573858 | ... L40: =IFERROR('Financials>'!L77/'Financials>'!L64,0) -> 0.1673913 | N40: =IFERROR(AVERAGE(C40:L40),0) -> 0.10579154 | O40: =IFERROR(MEDIAN(C40:L40),0) -> 0.095320338
B41: CFO/Total Debt | C41: =IFERROR('Financials>'!C77/'Financials>'!C49,0) -> 0.54641035 | D41: =IFERROR('Financials>'!D77/'Financials>'!D49,0) -> 0.38420446 | E41: =IFERROR('Financials>'!E77/'Financials>'!E49,0) -> 0.26820544 | F41: =IFERROR('Financials>'!F77/'Financials>'!F49,0) -> 0.17793209 | G41: =IFERROR('Financials>'!G77/'Financials>'!G49,0) -> 0.21342659 | H41: =IFERROR('Financials>'!H77/'Financials>'!H49,0) -> 0.20403774 | I41: =IFERROR('Financials>'!I77/'Financials>'!I49,0) -> 0.097521984 | J41: =IFERROR('Financials>'!J77/'Financials>'!J49,0) -> 0.26386617 | ... L41: =IFERROR('Financials>'!L77/'Financials>'!L49,0) -> 0.882052 | N41: =IFERROR(AVERAGE(C41:L41),0) -> 0.36708143 | O41: =IFERROR(MEDIAN(C41:L41),0) -> 0.26603581

Sheet Cashflow Data
C2: 42430 | D2: 42795 | E2: 43160 | F2: 43525 | G2: 43891 | H2: 44256 | I2: 44621 | J2: 44986 | K2: 45352 | L2: 45717
B3: Cash from Operating Activity - | C3: 37900 | D3: 30199 | E3: 23857 | F3: 18891 | G3: 26633 | H3: 29001 | I3: 14283 | J3: 35388 | K3: 67915 | L3: 63102
B4: Profit from operations | C4: 38626 | D4: 28840 | E4: 33312 | F4: 28771 | G4: 23352 | H4: 31198 | I4: 26943 | J4: 41694 | K4: 65106 | L4: 58937
B5: Receivables | C5: -2223 | D5: -4152 | E5: -10688 | F5: -9109 | G5: 9950 | H5: -5505 | I5: 185 | J5: -2213 | K5: -1876 | L5: 3573
B6: Inventory | C6: -5743 | D6: -6621 | E6: -3560 | F6: 2069 | G6: 2326 | H6: 3814 | I6: 472 | J6: -5665 | K6: -7265 | L6: 2127
B7: Payables | C7: 3947 | D7: 9301 | E7: 7320 | F7: -4692 | G7: -8085 | H7: 5748 | I7: -7012 | J7: 6945 | K7: 13706 | L7: 1303
B8: Loans Advances | C8: -520 | D8: 0 | E8: 0 | F8: 0 | G8: 0 | H8: 0 | I8: 0 | J8: 0 | K8: 0 | L8: 0
B9: Other WC items | C9: 5852 | D9: 4727 | E9: 494 | F9: 4512 | G9: 875 | H9: -4150 | I9: -4396 | J9: -2194 | K9: 2760 | L9: 1153
B10: Working capital changes | C10: 1313 | D10: 3254 | E10: -6434 | F10: -7221 | G10: 5065 | H10: -93 | I10: -10750 | J10: -3127 | K10: 7325 | L10: 8156
B11: Direct taxes | C11: -2040 | D11: -1895 | E11: -3021 | F11: -2659 | G11: -1785 | H11: -2105 | I11: -1910 | J11: -3179 | K11: -4516 | L11: -3991
B12: Cash from Investing Activity - | C12: -36694 | D12: -39571 | E12: -25139 | F12: -20878 | G12: -33115 | H12: -25672 | I12: -4444 | J12: -15417 | K12: -22781 | L12: -49982
B13: Fixed assets purchased | C13: -31503 | D13: -16072 | E13: -35079 | F13: -35304 | G13: -29702 | H13: -20205 | I13: -15168 | J13: -19230 | K13: -31414 | L13: -38042
B14: Fixed assets sold | C14: 59 | D14: 53 | E14: 30 | F14: 67 | G14: 171 | H14: 351 | I14: 230 | J14: 285 | K14: 231 | L14: 974
... B33: Net Cash Flow | C33: -2589 | D33: -3167 | E33: 730 | F33: 6843 | G33: -3092 | H33: 13232 | I33: 6459 | J33: -6272 | K33: 8128 | L33: -5666

Sheet HistoricalFS

Sheet Data>

Sheet Data Sheet
A1: COMPANY NAME | B1: TATA MOTORS PASSENGER VEHICLES LTD | E1: =IF(B2<>B3, "A NEW VERSION OF THE WORKSHEET IS AVAILABLE", "")
A2: LATEST VERSION | B2: 2.1 | E2: PLEASE DO NOT MAKE ANY CHANGES TO THIS SHEET
A3: CURRENT VERSION | B3: 2.1
A5: META
A6: Number of shares | B6: =IF(B9>0, B9/B8, 0) -> 368.0986
A7: Face Value | B7: 2
A8: Current Price | B8: 407.6
A9: Market Capitalization | B9: 150036.99
A15: PROFIT & LOSS
A16: Report Date | B16: 42460 | C16: 42825 | D16: 43190 | E16: 43555 | F16: 43921 | G16: 44286 | H16: 44651 | I16: 45016 | J16: 45382 | K16: 45747
A17: Sales | B17: 273045.6 | C17: 269692.51 | D17: 291550.48 | E17: 301938.4 | F17: 261067.97 | G17: 249794.75 | H17: 278453.62 | I17: 345966.97 | J17: 434016 | K17: 439695
A18: Raw Material Cost | B18: 166134.01 | C18: 173294.08 | D18: 187896.58 | E18: 194267.91 | F18: 164899.82 | G18: 153607.36 | H18: 179295.33 | I18: 231251.26 | J18: 274321 | K18: 268950
A19: Change in Inventory | B19: 2750.99 | C19: 7399.92 | D19: 2046.58 | E19: -2053.28 | F19: -2231.19 | G19: -4684.16 | H19: -1590.49 | I19: 4781.62 | J19: 1566 | K19: -2836
A20: Power and Fuel | B20: 1143.63 | C20: 1159.82 | D20: 1308.08 | E20: 1585.93 | F20: 1264.95 | G20: 1112.87 | H20: 2178.29 | I20: 2513.33 | J20: 2189 | K20: 2443
A21: Other Mfr. Exp | B21: 12101.53 | C21: 10067.37 | D21: 10971.66 | E21: 11694.54 | F21: 11541.51 | G21: 8273.17 | H21: 9427.38 | I21: 11765.97 | J21: 17446 | K21: 18813
A22: Employee Cost | B22: 28880.89 | C22: 28332.89 | D22: 30300.09 | E22: 33243.87 | F22: 30438.6 | G22: 27648.48 | H22: 30808.52 | I22: 33654.7 | J22: 41990 | K22: 47767
A23: Selling and admin | B23: 21991.9 | C23: 30039.38 | D23: 31004.58 | E23: 32719.8 | F23: 29248.32 | G23: 23015.79 | H23: 29205.4 | I23: 34839.19 | J23: 42765 | K23: 47099
A24: Other Expenses | B24: 7149.38 | C24: 4610.2 | D24: 658.39 | E24: 1708.74 | F24: 3456.51 | G24: -834.51 | H24: 1228.12 | I24: 4908.34 | J24: -953 | K24: -3429
A25: Other Income | B25: -2669.62 | C25: 1869.1 | D25: 5932.73 | E25: -26686.25 | F25: 101.71 | G25: -11117.83 | H25: 2424.05 | I25: 6663.97 | J25: 4792 | K25: 11774
A26: Depreciation | B26: 16710.78 | C26: 17904.99 | D26: 21553.59 | E26: 23590.63 | F26: 21425.43 | G26: 23546.71 | H26: 24835.69 | I26: 24860.36 | J26: 27239 | K26: 23256
A27: Interest | B27: 4889.08 | C27: 4238.01 | D27: 4681.79 | E27: 5758.6 | F27: 7243.33 | G27: 8097.17 | H27: 9311.86 | I27: 10225.48 | J27: 7594 | K27: 5083
... A30: Net profit | B30: 11579.31 | C30: 7454.36 | D30: 8988.91 | E30: -28826.23 | F30: -12070.85 | G30: -13451.39 | H30: -11441.47 | I30: 2414.29 | J30: 31399 | K30: 27830
A31: Dividend Amount | B31: 67.92 | I31: 766.02 | J31: 2301 | K31: 2208
A40: Quarters
A41: Report Date | B41: 45016 | C41: 45107 | D41: 45199 | E41: 45291 | F41: 45382 | G41: 45473 | H41: 45565 | I41: 45657 | J41: 45747 | K41: 45838
A42: Sales | B42: 105932.35 | C42: 102236 | D42: 105129 | E42: 110577 | F42: 119033 | G42: 107102 | H42: 101450 | I42: 112608 | J42: 119503 | K42: 104407
A43: Expenses | B43: 92817.95 | C43: 89019 | D43: 91362 | E43: 95159 | F43: 102348 | G43: 91854 | H43: 89291 | I43: 100185 | J43: 102685 | K43: 94183
A44: Other Income | B44: 1452.86 | C44: 895 | D44: 1557 | E44: 1604 | F44: 1412 | G44: 6553 | H44: 1647 | I44: 1700 | J44: 1057 | K44: 1595
A45: Depreciation | B45: 7050.2 | C45: 6633 | D45: 6637 | E45: 6850 | F45: 7143 | G45: 6565 | H45: 6005 | I45: 5399 | J45: 5295 | K45: 5320
A46: Interest | B46: 2641.67 | C46: 2615 | D46: 2652 | E46: 2485 | F46: 1645 | G46: 1471 | H46: 2034 | I46: 1119 | J46: 1076 | K46: 938
A47: Profit before tax | B47: 4875.39 | C47: 4864 | D47: 6035 | E47: 7687 | F47: 9309 | G47: 13765 | H47: 5767 | I47: 7605 | J47: 11504 | K47: 5561
A48: Tax | B48: -620.65 | C48: 1563 | D48: 2203 | E48: 542 | F48: -8219 | G48: 3178 | H48: 2317 | I48: 2120 | J48: 2948 | K48: 1558
A49: Net profit | B49: 5407.79 | C49: 3203 | D49: 3764 | E49: 7025 | F49: 17407 | G49: 10514 | H49: 3343 | I49: 5406 | J49: 8470 | K49: 3924
A50: Operating Profit | B50: 13114.4 | C50: 13217 | D50: 13767 | E50: 15418 | F50: 16685 | G50: 15248 | H50: 12159 | I50: 12423 | J50: 16818 | K50: 10224
A55: BALANCE SHEET
A56: Report Date | B56: 42460 | C56: 42825 | D56: 43190 | E56: 43555 | F56: 43921 | G56: 44286 | H56: 44651 | I56: 45016 | J56: 45382 | K56: 45747
A57: Equity Share Capital | B57: 679.18 | C57: 679.22 | D57: 679.22 | E57: 679.22 | F57: 719.54 | G57: 765.81 | H57: 765.88 | I57: 766.02 | J57: 767 | K57: 736
A58: Reserves | B58: 78273.23 | C58: 57382.67 | D58: 94748.69 | E58: 59500.34 | F58: 62358.99 | G58: 54480.91 | H58: 43795.36 | I58: 44555.77 | J58: 84151 | K58: 115408
A59: Borrowings | B59: 69359.96 | C59: 78603.98 | D59: 88950.47 | E59: 106175.34 | F59: 124787.64 | G59: 142130.57 | H59: 146449.03 | I59: 134113.44 | J59: 107264 | K59: 71540
A60: Other Liabilities | B60: 114871.75 | C60: 135914.49 | D60: 142813.43 | E60: 139348.59 | F60: 132313.22 | G60: 144192.62 | H60: 138051.22 | I60: 155239.2 | J60: 177339 | K60: 189289
...
